2019-07-28 15:12:52 connectionpool.py [line:206] DEBUG: Starting new HTTP connection (1): 60.13.42.94:9999
2019-07-28 15:12:52 httpbin_validator.py [line:100] ERROR: HTTPConnectionPool(host='60.13.42.94', port=9999): Max retries exceeded with url: http://httpbin.org/get (Caused by ProxyError('Cannot connect to proxy.', NewConnectionError('<urllib3.connection.HTTPConnection object at 0x7fec673939b0>: Failed to establish a new connection: [Errno 111] Connection refused',)))
Traceback (most recent call last):
  File "/home/susu/.virtualenvs/ipproxy_py3/lib/python3.5/site-packages/urllib3/connection.py", line 160, in _new_conn
    (self._dns_host, self.port), self.timeout, **extra_kw)
  File "/home/susu/.virtualenvs/ipproxy_py3/lib/python3.5/site-packages/urllib3/util/connection.py", line 80, in create_connection
    raise err
  File "/home/susu/.virtualenvs/ipproxy_py3/lib/python3.5/site-packages/urllib3/util/connection.py", line 70, in create_connection
    sock.connect(sa)
ConnectionRefusedError: [Errno 111] Connection refused

During handling of the above exception, another exception occurred:

Traceback (most recent call last):
  File "/home/susu/.virtualenvs/ipproxy_py3/lib/python3.5/site-packages/urllib3/connectionpool.py", line 603, in urlopen
    chunked=chunked)
  File "/home/susu/.virtualenvs/ipproxy_py3/lib/python3.5/site-packages/urllib3/connectionpool.py", line 355, in _make_request
    conn.request(method, url, **httplib_request_kw)
  File "/usr/lib/python3.5/http/client.py", line 1106, in request
    self._send_request(method, url, body, headers)
  File "/usr/lib/python3.5/http/client.py", line 1151, in _send_request
    self.endheaders(body)
  File "/usr/lib/python3.5/http/client.py", line 1102, in endheaders
    self._send_output(message_body)
  File "/usr/lib/python3.5/http/client.py", line 934, in _send_output
    self.send(msg)
  File "/usr/lib/python3.5/http/client.py", line 877, in send
    self.connect()
  File "/home/susu/.virtualenvs/ipproxy_py3/lib/python3.5/site-packages/urllib3/connection.py", line 183, in connect
    conn = self._new_conn()
  File "/home/susu/.virtualenvs/ipproxy_py3/lib/python3.5/site-packages/urllib3/connection.py", line 169, in _new_conn
    self, "Failed to establish a new connection: %s" % e)
urllib3.exceptions.NewConnectionError: <urllib3.connection.HTTPConnection object at 0x7fec673939b0>: Failed to establish a new connection: [Errno 111] Connection refused

During handling of the above exception, another exception occurred:

Traceback (most recent call last):
  File "/home/susu/.virtualenvs/ipproxy_py3/lib/python3.5/site-packages/requests/adapters.py", line 449, in send
    timeout=timeout
  File "/home/susu/.virtualenvs/ipproxy_py3/lib/python3.5/site-packages/urllib3/connectionpool.py", line 641, in urlopen
    _stacktrace=sys.exc_info()[2])
  File "/home/susu/.virtualenvs/ipproxy_py3/lib/python3.5/site-packages/urllib3/util/retry.py", line 399, in increment
    raise MaxRetryError(_pool, url, error or ResponseError(cause))
urllib3.exceptions.MaxRetryError: HTTPConnectionPool(host='60.13.42.94', port=9999): Max retries exceeded with url: http://httpbin.org/get (Caused by ProxyError('Cannot connect to proxy.', NewConnectionError('<urllib3.connection.HTTPConnection object at 0x7fec673939b0>: Failed to establish a new connection: [Errno 111] Connection refused',)))

During handling of the above exception, another exception occurred:

Traceback (most recent call last):
  File "/home/susu/桌面/就业/10_爬虫/07_IpProxyPool/IPProxyPool/proxy_validate/httpbin_validator.py", line 74, in http_check_proxies
    timeout=CHECK_TIMEOUT)
  File "/home/susu/.virtualenvs/ipproxy_py3/lib/python3.5/site-packages/requests/api.py", line 75, in get
    return request('get', url, params=params, **kwargs)
  File "/home/susu/.virtualenvs/ipproxy_py3/lib/python3.5/site-packages/requests/api.py", line 60, in request
    return session.request(method=method, url=url, **kwargs)
  File "/home/susu/.virtualenvs/ipproxy_py3/lib/python3.5/site-packages/requests/sessions.py", line 533, in request
    resp = self.send(prep, **send_kwargs)
  File "/home/susu/.virtualenvs/ipproxy_py3/lib/python3.5/site-packages/requests/sessions.py", line 646, in send
    r = adapter.send(request, **kwargs)
  File "/home/susu/.virtualenvs/ipproxy_py3/lib/python3.5/site-packages/requests/adapters.py", line 510, in send
    raise ProxyError(e, request=request)
requests.exceptions.ProxyError: HTTPConnectionPool(host='60.13.42.94', port=9999): Max retries exceeded with url: http://httpbin.org/get (Caused by ProxyError('Cannot connect to proxy.', NewConnectionError('<urllib3.connection.HTTPConnection object at 0x7fec673939b0>: Failed to establish a new connection: [Errno 111] Connection refused',)))
2019-07-28 15:12:52 connectionpool.py [line:815] DEBUG: Starting new HTTPS connection (1): httpbin.org:443
2019-07-28 15:12:52 httpbin_validator.py [line:100] ERROR: HTTPSConnectionPool(host='httpbin.org', port=443): Max retries exceeded with url: /get (Caused by ProxyError('Cannot connect to proxy.', NewConnectionError('<urllib3.connection.VerifiedHTTPSConnection object at 0x7fec66240198>: Failed to establish a new connection: [Errno 111] Connection refused',)))
Traceback (most recent call last):
  File "/home/susu/.virtualenvs/ipproxy_py3/lib/python3.5/site-packages/urllib3/connection.py", line 160, in _new_conn
    (self._dns_host, self.port), self.timeout, **extra_kw)
  File "/home/susu/.virtualenvs/ipproxy_py3/lib/python3.5/site-packages/urllib3/util/connection.py", line 80, in create_connection
    raise err
  File "/home/susu/.virtualenvs/ipproxy_py3/lib/python3.5/site-packages/urllib3/util/connection.py", line 70, in create_connection
    sock.connect(sa)
ConnectionRefusedError: [Errno 111] Connection refused

During handling of the above exception, another exception occurred:

Traceback (most recent call last):
  File "/home/susu/.virtualenvs/ipproxy_py3/lib/python3.5/site-packages/urllib3/connectionpool.py", line 597, in urlopen
    self._prepare_proxy(conn)
  File "/home/susu/.virtualenvs/ipproxy_py3/lib/python3.5/site-packages/urllib3/connectionpool.py", line 807, in _prepare_proxy
    conn.connect()
  File "/home/susu/.virtualenvs/ipproxy_py3/lib/python3.5/site-packages/urllib3/connection.py", line 316, in connect
    conn = self._new_conn()
  File "/home/susu/.virtualenvs/ipproxy_py3/lib/python3.5/site-packages/urllib3/connection.py", line 169, in _new_conn
    self, "Failed to establish a new connection: %s" % e)
urllib3.exceptions.NewConnectionError: <urllib3.connection.VerifiedHTTPSConnection object at 0x7fec66240198>: Failed to establish a new connection: [Errno 111] Connection refused

During handling of the above exception, another exception occurred:

Traceback (most recent call last):
  File "/home/susu/.virtualenvs/ipproxy_py3/lib/python3.5/site-packages/requests/adapters.py", line 449, in send
    timeout=timeout
  File "/home/susu/.virtualenvs/ipproxy_py3/lib/python3.5/site-packages/urllib3/connectionpool.py", line 641, in urlopen
    _stacktrace=sys.exc_info()[2])
  File "/home/susu/.virtualenvs/ipproxy_py3/lib/python3.5/site-packages/urllib3/util/retry.py", line 399, in increment
    raise MaxRetryError(_pool, url, error or ResponseError(cause))
urllib3.exceptions.MaxRetryError: HTTPSConnectionPool(host='httpbin.org', port=443): Max retries exceeded with url: /get (Caused by ProxyError('Cannot connect to proxy.', NewConnectionError('<urllib3.connection.VerifiedHTTPSConnection object at 0x7fec66240198>: Failed to establish a new connection: [Errno 111] Connection refused',)))

During handling of the above exception, another exception occurred:

Traceback (most recent call last):
  File "/home/susu/桌面/就业/10_爬虫/07_IpProxyPool/IPProxyPool/proxy_validate/httpbin_validator.py", line 74, in http_check_proxies
    timeout=CHECK_TIMEOUT)
  File "/home/susu/.virtualenvs/ipproxy_py3/lib/python3.5/site-packages/requests/api.py", line 75, in get
    return request('get', url, params=params, **kwargs)
  File "/home/susu/.virtualenvs/ipproxy_py3/lib/python3.5/site-packages/requests/api.py", line 60, in request
    return session.request(method=method, url=url, **kwargs)
  File "/home/susu/.virtualenvs/ipproxy_py3/lib/python3.5/site-packages/requests/sessions.py", line 533, in request
    resp = self.send(prep, **send_kwargs)
  File "/home/susu/.virtualenvs/ipproxy_py3/lib/python3.5/site-packages/requests/sessions.py", line 646, in send
    r = adapter.send(request, **kwargs)
  File "/home/susu/.virtualenvs/ipproxy_py3/lib/python3.5/site-packages/requests/adapters.py", line 510, in send
    raise ProxyError(e, request=request)
requests.exceptions.ProxyError: HTTPSConnectionPool(host='httpbin.org', port=443): Max retries exceeded with url: /get (Caused by ProxyError('Cannot connect to proxy.', NewConnectionError('<urllib3.connection.VerifiedHTTPSConnection object at 0x7fec66240198>: Failed to establish a new connection: [Errno 111] Connection refused',)))
